
2017-12-07 00:06:03,110|WARNING|Exiting immediately!
2017-12-07 00:06:29,970|WARNING|Exiting immediately!
2017-12-07 02:35:15,131|ERROR|Error while getting Updates: Timed out
2017-12-07 02:35:15,156|WARNING|Update "None" caused error "Timed out"
2017-12-07 02:35:48,498|ERROR|Error while getting Updates: Timed out
2017-12-07 02:35:48,498|WARNING|Update "None" caused error "Timed out"
2017-12-07 02:36:26,755|ERROR|Error while getting Updates: Internal server error: restart (500)
2017-12-07 02:36:26,756|WARNING|Update "None" caused error "Internal server error: restart (500)"
2017-12-07 02:36:30,607|ERROR|Error while getting Updates: Invalid server response
2017-12-07 02:36:30,608|WARNING|Update "None" caused error "Invalid server response"
2017-12-07 02:36:32,149|ERROR|Error while getting Updates: Invalid server response
2017-12-07 02:36:32,150|WARNING|Update "None" caused error "Invalid server response"
2017-12-07 02:36:34,442|ERROR|Error while getting Updates: Invalid server response
2017-12-07 02:36:34,444|WARNING|Update "None" caused error "Invalid server response"
2017-12-07 02:36:37,859|ERROR|Error while getting Updates: Invalid server response
2017-12-07 02:36:37,861|WARNING|Update "None" caused error "Invalid server response"
2017-12-07 02:36:54,937|ERROR|Error while getting Updates: Timed out
2017-12-07 02:36:54,938|WARNING|Update "None" caused error "Timed out"
2017-12-07 02:37:35,042|ERROR|Error while getting Updates: Timed out
2017-12-07 02:37:35,059|WARNING|Update "None" caused error "Timed out"
2017-12-07 02:42:54,954|ERROR|Error while getting Updates: Timed out
2017-12-07 02:42:54,968|WARNING|Update "None" caused error "Timed out"
2017-12-07 02:43:08,236|ERROR|Error while getting Updates: Timed out
2017-12-07 02:43:08,236|WARNING|Update "None" caused error "Timed out"
2017-12-07 03:16:02,765|WARNING|Exiting immediately!
2017-12-07 20:01:24,502|WARNING|Retrying (Retry(total=2, connect=None, read=None, redirect=None)) after connection broken by 'NewConnectionError('<telegram.vendor.ptb_urllib3.urllib3.connection.VerifiedHTTPSConnection object at 0x7fc1defc9be0>: Failed to establish a new connection: [Errno -2] Name or service not known',)': /bot327964142:AAENWdsnS4WB0H1QJDv6nkTAfLKEHt2ML0w/setWebhook
2017-12-07 20:01:24,514|WARNING|Retrying (Retry(total=1, connect=None, read=None, redirect=None)) after connection broken by 'NewConnectionError('<telegram.vendor.ptb_urllib3.urllib3.connection.VerifiedHTTPSConnection object at 0x7fc1defc9cf8>: Failed to establish a new connection: [Errno -2] Name or service not known',)': /bot327964142:AAENWdsnS4WB0H1QJDv6nkTAfLKEHt2ML0w/setWebhook
2017-12-07 20:01:24,515|WARNING|Retrying (Retry(total=0, connect=None, read=None, redirect=None)) after connection broken by 'NewConnectionError('<telegram.vendor.ptb_urllib3.urllib3.connection.VerifiedHTTPSConnection object at 0x7fc1defda1d0>: Failed to establish a new connection: [Errno -2] Name or service not known',)': /bot327964142:AAENWdsnS4WB0H1QJDv6nkTAfLKEHt2ML0w/setWebhook
2017-12-07 20:01:24,516|ERROR|error in bootstrap phase; try=0 max_retries=0
Traceback (most recent call last):
  File "/home/matteo/Scrivania/PagRom_CPanel/lib/python3.6/site-packages/telegram/vendor/ptb_urllib3/urllib3/connection.py", line 141, in _new_conn
    (self.host, self.port), self.timeout, **extra_kw)
  File "/home/matteo/Scrivania/PagRom_CPanel/lib/python3.6/site-packages/telegram/vendor/ptb_urllib3/urllib3/util/connection.py", line 60, in create_connection
    for res in socket.getaddrinfo(host, port, family, socket.SOCK_STREAM):
  File "/usr/lib/python3.6/socket.py", line 745, in getaddrinfo
    for res in _socket.getaddrinfo(host, port, family, type, proto, flags):
socket.gaierror: [Errno -2] Name or service not known

During handling of the above exception, another exception occurred:

Traceback (most recent call last):
  File "/home/matteo/Scrivania/PagRom_CPanel/lib/python3.6/site-packages/telegram/vendor/ptb_urllib3/urllib3/connectionpool.py", line 617, in urlopen
    chunked=chunked)
  File "/home/matteo/Scrivania/PagRom_CPanel/lib/python3.6/site-packages/telegram/vendor/ptb_urllib3/urllib3/connectionpool.py", line 360, in _make_request
    self._validate_conn(conn)
  File "/home/matteo/Scrivania/PagRom_CPanel/lib/python3.6/site-packages/telegram/vendor/ptb_urllib3/urllib3/connectionpool.py", line 857, in _validate_conn
    super(HTTPSConnectionPool, self)._validate_conn(conn)
  File "/home/matteo/Scrivania/PagRom_CPanel/lib/python3.6/site-packages/telegram/vendor/ptb_urllib3/urllib3/connectionpool.py", line 289, in _validate_conn
    conn.connect()
  File "/home/matteo/Scrivania/PagRom_CPanel/lib/python3.6/site-packages/telegram/vendor/ptb_urllib3/urllib3/connection.py", line 284, in connect
    conn = self._new_conn()
  File "/home/matteo/Scrivania/PagRom_CPanel/lib/python3.6/site-packages/telegram/vendor/ptb_urllib3/urllib3/connection.py", line 150, in _new_conn
    self, "Failed to establish a new connection: %s" % e)
telegram.vendor.ptb_urllib3.urllib3.exceptions.NewConnectionError: <telegram.vendor.ptb_urllib3.urllib3.connection.VerifiedHTTPSConnection object at 0x7fc1dc763208>: Failed to establish a new connection: [Errno -2] Name or service not known

During handling of the above exception, another exception occurred:

Traceback (most recent call last):
  File "/home/matteo/Scrivania/PagRom_CPanel/lib/python3.6/site-packages/telegram/utils/request.py", line 190, in _request_wrapper
    resp = self._con_pool.request(*args, **kwargs)
  File "/home/matteo/Scrivania/PagRom_CPanel/lib/python3.6/site-packages/telegram/vendor/ptb_urllib3/urllib3/request.py", line 70, in request
    **urlopen_kw)
  File "/home/matteo/Scrivania/PagRom_CPanel/lib/python3.6/site-packages/telegram/vendor/ptb_urllib3/urllib3/request.py", line 148, in request_encode_body
    return self.urlopen(method, url, **extra_kw)
  File "/home/matteo/Scrivania/PagRom_CPanel/lib/python3.6/site-packages/telegram/vendor/ptb_urllib3/urllib3/poolmanager.py", line 244, in urlopen
    response = conn.urlopen(method, u.request_uri, **kw)
  File "/home/matteo/Scrivania/PagRom_CPanel/lib/python3.6/site-packages/telegram/vendor/ptb_urllib3/urllib3/connectionpool.py", line 695, in urlopen
    **response_kw)
  File "/home/matteo/Scrivania/PagRom_CPanel/lib/python3.6/site-packages/telegram/vendor/ptb_urllib3/urllib3/connectionpool.py", line 695, in urlopen
    **response_kw)
  File "/home/matteo/Scrivania/PagRom_CPanel/lib/python3.6/site-packages/telegram/vendor/ptb_urllib3/urllib3/connectionpool.py", line 695, in urlopen
    **response_kw)
  File "/home/matteo/Scrivania/PagRom_CPanel/lib/python3.6/site-packages/telegram/vendor/ptb_urllib3/urllib3/connectionpool.py", line 666, in urlopen
    _stacktrace=sys.exc_info()[2])
  File "/home/matteo/Scrivania/PagRom_CPanel/lib/python3.6/site-packages/telegram/vendor/ptb_urllib3/urllib3/util/retry.py", line 376, in increment
    raise MaxRetryError(_pool, url, error or ResponseError(cause))
telegram.vendor.ptb_urllib3.urllib3.exceptions.MaxRetryError: HTTPSConnectionPool(host='api.telegram.org', port=443): Max retries exceeded with url: /bot327964142:AAENWdsnS4WB0H1QJDv6nkTAfLKEHt2ML0w/setWebhook (Caused by NewConnectionError('<telegram.vendor.ptb_urllib3.urllib3.connection.VerifiedHTTPSConnection object at 0x7fc1dc763208>: Failed to establish a new connection: [Errno -2] Name or service not known',))

During handling of the above exception, another exception occurred:

Traceback (most recent call last):
  File "/home/matteo/Scrivania/PagRom_CPanel/lib/python3.6/site-packages/telegram/ext/updater.py", line 387, in _bootstrap
    url=webhook_url, certificate=cert, allowed_updates=allowed_updates)
  File "/home/matteo/Scrivania/PagRom_CPanel/lib/python3.6/site-packages/telegram/bot.py", line 57, in decorator
    result = func(self, *args, **kwargs)
  File "/home/matteo/Scrivania/PagRom_CPanel/lib/python3.6/site-packages/telegram/bot.py", line 1765, in set_webhook
    result = self._request.post(url_, data, timeout=timeout)
  File "/home/matteo/Scrivania/PagRom_CPanel/lib/python3.6/site-packages/telegram/utils/request.py", line 272, in post
    **urlopen_kwargs)
  File "/home/matteo/Scrivania/PagRom_CPanel/lib/python3.6/site-packages/telegram/utils/request.py", line 196, in _request_wrapper
    raise NetworkError('urllib3 HTTPError {0}'.format(error))
telegram.error.NetworkError: urllib3 HTTPError HTTPSConnectionPool(host='api.telegram.org', port=443): Max retries exceeded with url: /bot327964142:AAENWdsnS4WB0H1QJDv6nkTAfLKEHt2ML0w/setWebhook (Caused by NewConnectionError('<telegram.vendor.ptb_urllib3.urllib3.connection.VerifiedHTTPSConnection object at 0x7fc1dc763208>: Failed to establish a new connection: [Errno -2] Name or service not known',))
2017-12-07 20:01:24,593|ERROR|unhandled exception
Traceback (most recent call last):
  File "/home/matteo/Scrivania/PagRom_CPanel/lib/python3.6/site-packages/telegram/vendor/ptb_urllib3/urllib3/connection.py", line 141, in _new_conn
    (self.host, self.port), self.timeout, **extra_kw)
  File "/home/matteo/Scrivania/PagRom_CPanel/lib/python3.6/site-packages/telegram/vendor/ptb_urllib3/urllib3/util/connection.py", line 60, in create_connection
    for res in socket.getaddrinfo(host, port, family, socket.SOCK_STREAM):
  File "/usr/lib/python3.6/socket.py", line 745, in getaddrinfo
    for res in _socket.getaddrinfo(host, port, family, type, proto, flags):
socket.gaierror: [Errno -2] Name or service not known

During handling of the above exception, another exception occurred:

Traceback (most recent call last):
  File "/home/matteo/Scrivania/PagRom_CPanel/lib/python3.6/site-packages/telegram/vendor/ptb_urllib3/urllib3/connectionpool.py", line 617, in urlopen
    chunked=chunked)
  File "/home/matteo/Scrivania/PagRom_CPanel/lib/python3.6/site-packages/telegram/vendor/ptb_urllib3/urllib3/connectionpool.py", line 360, in _make_request
    self._validate_conn(conn)
  File "/home/matteo/Scrivania/PagRom_CPanel/lib/python3.6/site-packages/telegram/vendor/ptb_urllib3/urllib3/connectionpool.py", line 857, in _validate_conn
    super(HTTPSConnectionPool, self)._validate_conn(conn)
  File "/home/matteo/Scrivania/PagRom_CPanel/lib/python3.6/site-packages/telegram/vendor/ptb_urllib3/urllib3/connectionpool.py", line 289, in _validate_conn
    conn.connect()
  File "/home/matteo/Scrivania/PagRom_CPanel/lib/python3.6/site-packages/telegram/vendor/ptb_urllib3/urllib3/connection.py", line 284, in connect
    conn = self._new_conn()
  File "/home/matteo/Scrivania/PagRom_CPanel/lib/python3.6/site-packages/telegram/vendor/ptb_urllib3/urllib3/connection.py", line 150, in _new_conn
    self, "Failed to establish a new connection: %s" % e)
telegram.vendor.ptb_urllib3.urllib3.exceptions.NewConnectionError: <telegram.vendor.ptb_urllib3.urllib3.connection.VerifiedHTTPSConnection object at 0x7fc1dc763208>: Failed to establish a new connection: [Errno -2] Name or service not known

During handling of the above exception, another exception occurred:

Traceback (most recent call last):
  File "/home/matteo/Scrivania/PagRom_CPanel/lib/python3.6/site-packages/telegram/utils/request.py", line 190, in _request_wrapper
    resp = self._con_pool.request(*args, **kwargs)
  File "/home/matteo/Scrivania/PagRom_CPanel/lib/python3.6/site-packages/telegram/vendor/ptb_urllib3/urllib3/request.py", line 70, in request
    **urlopen_kw)
  File "/home/matteo/Scrivania/PagRom_CPanel/lib/python3.6/site-packages/telegram/vendor/ptb_urllib3/urllib3/request.py", line 148, in request_encode_body
    return self.urlopen(method, url, **extra_kw)
  File "/home/matteo/Scrivania/PagRom_CPanel/lib/python3.6/site-packages/telegram/vendor/ptb_urllib3/urllib3/poolmanager.py", line 244, in urlopen
    response = conn.urlopen(method, u.request_uri, **kw)
  File "/home/matteo/Scrivania/PagRom_CPanel/lib/python3.6/site-packages/telegram/vendor/ptb_urllib3/urllib3/connectionpool.py", line 695, in urlopen
    **response_kw)
  File "/home/matteo/Scrivania/PagRom_CPanel/lib/python3.6/site-packages/telegram/vendor/ptb_urllib3/urllib3/connectionpool.py", line 695, in urlopen
    **response_kw)
  File "/home/matteo/Scrivania/PagRom_CPanel/lib/python3.6/site-packages/telegram/vendor/ptb_urllib3/urllib3/connectionpool.py", line 695, in urlopen
    **response_kw)
  File "/home/matteo/Scrivania/PagRom_CPanel/lib/python3.6/site-packages/telegram/vendor/ptb_urllib3/urllib3/connectionpool.py", line 666, in urlopen
    _stacktrace=sys.exc_info()[2])
  File "/home/matteo/Scrivania/PagRom_CPanel/lib/python3.6/site-packages/telegram/vendor/ptb_urllib3/urllib3/util/retry.py", line 376, in increment
    raise MaxRetryError(_pool, url, error or ResponseError(cause))
telegram.vendor.ptb_urllib3.urllib3.exceptions.MaxRetryError: HTTPSConnectionPool(host='api.telegram.org', port=443): Max retries exceeded with url: /bot327964142:AAENWdsnS4WB0H1QJDv6nkTAfLKEHt2ML0w/setWebhook (Caused by NewConnectionError('<telegram.vendor.ptb_urllib3.urllib3.connection.VerifiedHTTPSConnection object at 0x7fc1dc763208>: Failed to establish a new connection: [Errno -2] Name or service not known',))

During handling of the above exception, another exception occurred:

Traceback (most recent call last):
  File "/home/matteo/Scrivania/PagRom_CPanel/lib/python3.6/site-packages/telegram/ext/updater.py", line 149, in _thread_wrapper
    target(*args, **kwargs)
  File "/home/matteo/Scrivania/PagRom_CPanel/lib/python3.6/site-packages/telegram/ext/updater.py", line 275, in _start_polling
    self._bootstrap(bootstrap_retries, clean=clean, webhook_url='', allowed_updates=None)
  File "/home/matteo/Scrivania/PagRom_CPanel/lib/python3.6/site-packages/telegram/ext/updater.py", line 387, in _bootstrap
    url=webhook_url, certificate=cert, allowed_updates=allowed_updates)
  File "/home/matteo/Scrivania/PagRom_CPanel/lib/python3.6/site-packages/telegram/bot.py", line 57, in decorator
    result = func(self, *args, **kwargs)
  File "/home/matteo/Scrivania/PagRom_CPanel/lib/python3.6/site-packages/telegram/bot.py", line 1765, in set_webhook
    result = self._request.post(url_, data, timeout=timeout)
  File "/home/matteo/Scrivania/PagRom_CPanel/lib/python3.6/site-packages/telegram/utils/request.py", line 272, in post
    **urlopen_kwargs)
  File "/home/matteo/Scrivania/PagRom_CPanel/lib/python3.6/site-packages/telegram/utils/request.py", line 196, in _request_wrapper
    raise NetworkError('urllib3 HTTPError {0}'.format(error))
telegram.error.NetworkError: urllib3 HTTPError HTTPSConnectionPool(host='api.telegram.org', port=443): Max retries exceeded with url: /bot327964142:AAENWdsnS4WB0H1QJDv6nkTAfLKEHt2ML0w/setWebhook (Caused by NewConnectionError('<telegram.vendor.ptb_urllib3.urllib3.connection.VerifiedHTTPSConnection object at 0x7fc1dc763208>: Failed to establish a new connection: [Errno -2] Name or service not known',))
2017-12-07 20:01:25,470|CRITICAL|stopping due to exception in another thread
2017-12-07 20:03:54,721|ERROR|An uncaught error was raised while processing the update
Traceback (most recent call last):
  File "/home/matteo/Scrivania/PagRom_CPanel/lib/python3.6/site-packages/telegram/ext/dispatcher.py", line 270, in process_update
    handler.handle_update(update, self)
  File "/home/matteo/Scrivania/PagRom_CPanel/lib/python3.6/site-packages/telegram/ext/commandhandler.py", line 171, in handle_update
    return self.callback(dispatcher.bot, update, **optional_args)
  File "test.py", line 24, in start
    reply_markup=ReplyKeyboardMarkup(reply_keyboard, one_time_keyboard=True))
NameError: name 'reply_keyboard' is not defined
2017-12-07 20:04:32,975|ERROR|An uncaught error was raised while processing the update
Traceback (most recent call last):
  File "/home/matteo/Scrivania/PagRom_CPanel/lib/python3.6/site-packages/telegram/ext/dispatcher.py", line 270, in process_update
    handler.handle_update(update, self)
  File "/home/matteo/Scrivania/PagRom_CPanel/lib/python3.6/site-packages/telegram/ext/commandhandler.py", line 171, in handle_update
    return self.callback(dispatcher.bot, update, **optional_args)
  File "test.py", line 24, in start
    reply_markup=ReplyKeyboardMarkup(reply_keyboard, one_time_keyboard=True))
NameError: name 'reply_keyboard' is not defined
2017-12-07 20:04:56,374|WARNING|Exiting immediately!
2017-12-07 20:07:25,678|ERROR|An uncaught error was raised while processing the update
Traceback (most recent call last):
  File "/home/matteo/Scrivania/PagRom_CPanel/lib/python3.6/site-packages/telegram/ext/dispatcher.py", line 270, in process_update
    handler.handle_update(update, self)
  File "/home/matteo/Scrivania/PagRom_CPanel/lib/python3.6/site-packages/telegram/ext/commandhandler.py", line 171, in handle_update
    return self.callback(dispatcher.bot, update, **optional_args)
  File "test.py", line 24, in start
    reply_markup=ReplyKeyboardMarkup(reply_keyboard, one_time_keyboard=True))
NameError: name 'reply_keyboard' is not defined
2017-12-07 20:07:38,215|ERROR|An uncaught error was raised while processing the update
Traceback (most recent call last):
  File "/home/matteo/Scrivania/PagRom_CPanel/lib/python3.6/site-packages/telegram/ext/dispatcher.py", line 270, in process_update
    handler.handle_update(update, self)
  File "/home/matteo/Scrivania/PagRom_CPanel/lib/python3.6/site-packages/telegram/ext/commandhandler.py", line 171, in handle_update
    return self.callback(dispatcher.bot, update, **optional_args)
  File "test.py", line 24, in start
    reply_markup=ReplyKeyboardMarkup(reply_keyboard, one_time_keyboard=True))
NameError: name 'reply_keyboard' is not defined
2017-12-07 20:07:42,003|ERROR|An uncaught error was raised while processing the update
Traceback (most recent call last):
  File "/home/matteo/Scrivania/PagRom_CPanel/lib/python3.6/site-packages/telegram/ext/dispatcher.py", line 270, in process_update
    handler.handle_update(update, self)
  File "/home/matteo/Scrivania/PagRom_CPanel/lib/python3.6/site-packages/telegram/ext/commandhandler.py", line 171, in handle_update
    return self.callback(dispatcher.bot, update, **optional_args)
  File "test.py", line 24, in start
    reply_markup=ReplyKeyboardMarkup(reply_keyboard, one_time_keyboard=True))
NameError: name 'reply_keyboard' is not defined
2017-12-07 20:07:42,696|ERROR|An uncaught error was raised while processing the update
Traceback (most recent call last):
  File "/home/matteo/Scrivania/PagRom_CPanel/lib/python3.6/site-packages/telegram/ext/dispatcher.py", line 270, in process_update
    handler.handle_update(update, self)
  File "/home/matteo/Scrivania/PagRom_CPanel/lib/python3.6/site-packages/telegram/ext/commandhandler.py", line 171, in handle_update
    return self.callback(dispatcher.bot, update, **optional_args)
  File "test.py", line 24, in start
    reply_markup=ReplyKeyboardMarkup(reply_keyboard, one_time_keyboard=True))
NameError: name 'reply_keyboard' is not defined
2017-12-07 20:07:43,295|ERROR|An uncaught error was raised while processing the update
Traceback (most recent call last):
  File "/home/matteo/Scrivania/PagRom_CPanel/lib/python3.6/site-packages/telegram/ext/dispatcher.py", line 270, in process_update
    handler.handle_update(update, self)
  File "/home/matteo/Scrivania/PagRom_CPanel/lib/python3.6/site-packages/telegram/ext/commandhandler.py", line 171, in handle_update
    return self.callback(dispatcher.bot, update, **optional_args)
  File "test.py", line 24, in start
    reply_markup=ReplyKeyboardMarkup(reply_keyboard, one_time_keyboard=True))
NameError: name 'reply_keyboard' is not defined
2017-12-07 20:17:21,275|WARNING|Exiting immediately!
2017-12-07 23:40:31,304|ERROR|An uncaught error was raised while processing the update
Traceback (most recent call last):
  File "/home/matteo/Scrivania/PagRom_CPanel/lib/python3.6/site-packages/telegram/ext/dispatcher.py", line 270, in process_update
    handler.handle_update(update, self)
  File "/home/matteo/Scrivania/PagRom_CPanel/lib/python3.6/site-packages/telegram/ext/callbackqueryhandler.py", line 143, in handle_update
    return self.callback(dispatcher.bot, update, **optional_args)
  File "test.py", line 38, in button
    update.message.reply_text(text="hai selezionato l'opzione: {}".format(query.data),
AttributeError: 'NoneType' object has no attribute 'reply_text'
2017-12-07 23:40:34,469|ERROR|An uncaught error was raised while processing the update
Traceback (most recent call last):
  File "/home/matteo/Scrivania/PagRom_CPanel/lib/python3.6/site-packages/telegram/ext/dispatcher.py", line 270, in process_update
    handler.handle_update(update, self)
  File "/home/matteo/Scrivania/PagRom_CPanel/lib/python3.6/site-packages/telegram/ext/callbackqueryhandler.py", line 143, in handle_update
    return self.callback(dispatcher.bot, update, **optional_args)
  File "test.py", line 38, in button
    update.message.reply_text(text="hai selezionato l'opzione: {}".format(query.data),
AttributeError: 'NoneType' object has no attribute 'reply_text'
2017-12-07 23:40:35,643|ERROR|An uncaught error was raised while processing the update
Traceback (most recent call last):
  File "/home/matteo/Scrivania/PagRom_CPanel/lib/python3.6/site-packages/telegram/ext/dispatcher.py", line 270, in process_update
    handler.handle_update(update, self)
  File "/home/matteo/Scrivania/PagRom_CPanel/lib/python3.6/site-packages/telegram/ext/callbackqueryhandler.py", line 143, in handle_update
    return self.callback(dispatcher.bot, update, **optional_args)
  File "test.py", line 38, in button
    update.message.reply_text(text="hai selezionato l'opzione: {}".format(query.data),
AttributeError: 'NoneType' object has no attribute 'reply_text'
2017-12-07 23:41:38,674|ERROR|An uncaught error was raised while processing the update
Traceback (most recent call last):
  File "/home/matteo/Scrivania/PagRom_CPanel/lib/python3.6/site-packages/telegram/ext/dispatcher.py", line 270, in process_update
    handler.handle_update(update, self)
  File "/home/matteo/Scrivania/PagRom_CPanel/lib/python3.6/site-packages/telegram/ext/callbackqueryhandler.py", line 143, in handle_update
    return self.callback(dispatcher.bot, update, **optional_args)
  File "test.py", line 38, in button
    update.message.reply_text(text="hai selezionato l'opzione: {}".format(query.data),
AttributeError: 'NoneType' object has no attribute 'reply_text'
2017-12-07 23:41:39,610|ERROR|An uncaught error was raised while processing the update
Traceback (most recent call last):
  File "/home/matteo/Scrivania/PagRom_CPanel/lib/python3.6/site-packages/telegram/ext/dispatcher.py", line 270, in process_update
    handler.handle_update(update, self)
  File "/home/matteo/Scrivania/PagRom_CPanel/lib/python3.6/site-packages/telegram/ext/callbackqueryhandler.py", line 143, in handle_update
    return self.callback(dispatcher.bot, update, **optional_args)
  File "test.py", line 38, in button
    update.message.reply_text(text="hai selezionato l'opzione: {}".format(query.data),
AttributeError: 'NoneType' object has no attribute 'reply_text'
2017-12-07 23:41:40,142|ERROR|An uncaught error was raised while processing the update
Traceback (most recent call last):
  File "/home/matteo/Scrivania/PagRom_CPanel/lib/python3.6/site-packages/telegram/ext/dispatcher.py", line 270, in process_update
    handler.handle_update(update, self)
  File "/home/matteo/Scrivania/PagRom_CPanel/lib/python3.6/site-packages/telegram/ext/callbackqueryhandler.py", line 143, in handle_update
    return self.callback(dispatcher.bot, update, **optional_args)
  File "test.py", line 38, in button
    update.message.reply_text(text="hai selezionato l'opzione: {}".format(query.data),
AttributeError: 'NoneType' object has no attribute 'reply_text'
2017-12-07 23:41:40,551|ERROR|An uncaught error was raised while processing the update
Traceback (most recent call last):
  File "/home/matteo/Scrivania/PagRom_CPanel/lib/python3.6/site-packages/telegram/ext/dispatcher.py", line 270, in process_update
    handler.handle_update(update, self)
  File "/home/matteo/Scrivania/PagRom_CPanel/lib/python3.6/site-packages/telegram/ext/callbackqueryhandler.py", line 143, in handle_update
    return self.callback(dispatcher.bot, update, **optional_args)
  File "test.py", line 38, in button
    update.message.reply_text(text="hai selezionato l'opzione: {}".format(query.data),
AttributeError: 'NoneType' object has no attribute 'reply_text'
2017-12-07 23:41:40,874|ERROR|An uncaught error was raised while processing the update
Traceback (most recent call last):
  File "/home/matteo/Scrivania/PagRom_CPanel/lib/python3.6/site-packages/telegram/ext/dispatcher.py", line 270, in process_update
    handler.handle_update(update, self)
  File "/home/matteo/Scrivania/PagRom_CPanel/lib/python3.6/site-packages/telegram/ext/callbackqueryhandler.py", line 143, in handle_update
    return self.callback(dispatcher.bot, update, **optional_args)
  File "test.py", line 38, in button
    update.message.reply_text(text="hai selezionato l'opzione: {}".format(query.data),
AttributeError: 'NoneType' object has no attribute 'reply_text'
2017-12-07 23:41:44,092|ERROR|An uncaught error was raised while processing the update
Traceback (most recent call last):
  File "/home/matteo/Scrivania/PagRom_CPanel/lib/python3.6/site-packages/telegram/ext/dispatcher.py", line 270, in process_update
    handler.handle_update(update, self)
  File "/home/matteo/Scrivania/PagRom_CPanel/lib/python3.6/site-packages/telegram/ext/callbackqueryhandler.py", line 143, in handle_update
    return self.callback(dispatcher.bot, update, **optional_args)
  File "test.py", line 38, in button
    update.message.reply_text(text="hai selezionato l'opzione: {}".format(query.data),
AttributeError: 'NoneType' object has no attribute 'reply_text'
2017-12-07 23:42:50,115|WARNING|Exiting immediately!
2017-12-07 23:49:51,745|WARNING|Exiting immediately!
2017-12-08 00:02:43,572|ERROR|An uncaught error was raised while processing the update
Traceback (most recent call last):
  File "/home/matteo/Scrivania/PagRom_CPanel/lib/python3.6/site-packages/telegram/ext/dispatcher.py", line 270, in process_update
    handler.handle_update(update, self)
  File "/home/matteo/Scrivania/PagRom_CPanel/lib/python3.6/site-packages/telegram/ext/callbackqueryhandler.py", line 143, in handle_update
    return self.callback(dispatcher.bot, update, **optional_args)
  File "test.py", line 38, in button
    update.message.reply_text(text="hai selezionato l'opzione: {}".format(query.data))
AttributeError: 'NoneType' object has no attribute 'reply_text'
2017-12-08 00:02:45,924|ERROR|An uncaught error was raised while processing the update
Traceback (most recent call last):
  File "/home/matteo/Scrivania/PagRom_CPanel/lib/python3.6/site-packages/telegram/ext/dispatcher.py", line 270, in process_update
    handler.handle_update(update, self)
  File "/home/matteo/Scrivania/PagRom_CPanel/lib/python3.6/site-packages/telegram/ext/callbackqueryhandler.py", line 143, in handle_update
    return self.callback(dispatcher.bot, update, **optional_args)
  File "test.py", line 38, in button
    update.message.reply_text(text="hai selezionato l'opzione: {}".format(query.data))
AttributeError: 'NoneType' object has no attribute 'reply_text'
2017-12-08 00:02:46,706|ERROR|An uncaught error was raised while processing the update
Traceback (most recent call last):
  File "/home/matteo/Scrivania/PagRom_CPanel/lib/python3.6/site-packages/telegram/ext/dispatcher.py", line 270, in process_update
    handler.handle_update(update, self)
  File "/home/matteo/Scrivania/PagRom_CPanel/lib/python3.6/site-packages/telegram/ext/callbackqueryhandler.py", line 143, in handle_update
    return self.callback(dispatcher.bot, update, **optional_args)
  File "test.py", line 38, in button
    update.message.reply_text(text="hai selezionato l'opzione: {}".format(query.data))
AttributeError: 'NoneType' object has no attribute 'reply_text'
2017-12-08 00:24:54,575|ERROR|Error while getting Updates: Timed out
2017-12-08 00:50:32,344|ERROR|Error while getting Updates: Timed out
2017-12-08 00:55:00,379|WARNING|Exiting immediately!
2017-12-08 00:55:26,959|WARNING|A TelegramError was raised while processing the Update
2017-12-08 00:55:34,249|WARNING|A TelegramError was raised while processing the Update
2017-12-08 00:55:54,326|WARNING|Exiting immediately!
2017-12-08 01:05:52,659|WARNING|Exiting immediately!
2017-12-08 01:06:05,513|ERROR|An uncaught error was raised while processing the update
Traceback (most recent call last):
  File "/home/matteo/Scrivania/PagRom_CPanel/lib/python3.6/site-packages/telegram/ext/dispatcher.py", line 270, in process_update
    handler.handle_update(update, self)
  File "/home/matteo/Scrivania/PagRom_CPanel/lib/python3.6/site-packages/telegram/ext/callbackqueryhandler.py", line 143, in handle_update
    return self.callback(dispatcher.bot, update, **optional_args)
  File "test.py", line 37, in button
    callback_query_id=query.query_id)
AttributeError: 'CallbackQuery' object has no attribute 'query_id'
2017-12-08 01:06:07,791|ERROR|An uncaught error was raised while processing the update
Traceback (most recent call last):
  File "/home/matteo/Scrivania/PagRom_CPanel/lib/python3.6/site-packages/telegram/ext/dispatcher.py", line 270, in process_update
    handler.handle_update(update, self)
  File "/home/matteo/Scrivania/PagRom_CPanel/lib/python3.6/site-packages/telegram/ext/callbackqueryhandler.py", line 143, in handle_update
    return self.callback(dispatcher.bot, update, **optional_args)
  File "test.py", line 37, in button
    callback_query_id=query.query_id)
AttributeError: 'CallbackQuery' object has no attribute 'query_id'
2017-12-08 01:06:08,513|ERROR|An uncaught error was raised while processing the update
Traceback (most recent call last):
  File "/home/matteo/Scrivania/PagRom_CPanel/lib/python3.6/site-packages/telegram/ext/dispatcher.py", line 270, in process_update
    handler.handle_update(update, self)
  File "/home/matteo/Scrivania/PagRom_CPanel/lib/python3.6/site-packages/telegram/ext/callbackqueryhandler.py", line 143, in handle_update
    return self.callback(dispatcher.bot, update, **optional_args)
  File "test.py", line 37, in button
    callback_query_id=query.query_id)
AttributeError: 'CallbackQuery' object has no attribute 'query_id'
2017-12-08 01:06:35,956|WARNING|Exiting immediately!
2017-12-08 01:07:09,305|ERROR|An uncaught error was raised while processing the update
Traceback (most recent call last):
  File "/home/matteo/Scrivania/PagRom_CPanel/lib/python3.6/site-packages/telegram/ext/dispatcher.py", line 270, in process_update
    handler.handle_update(update, self)
  File "/home/matteo/Scrivania/PagRom_CPanel/lib/python3.6/site-packages/telegram/ext/callbackqueryhandler.py", line 143, in handle_update
    return self.callback(dispatcher.bot, update, **optional_args)
  File "test.py", line 38, in button
    callback_query_id=query.query_id)
AttributeError: 'CallbackQuery' object has no attribute 'query_id'
2017-12-08 01:09:28,129|WARNING|Exiting immediately!
2017-12-08 01:13:50,273|WARNING|Exiting immediately!
2017-12-08 01:14:00,371|ERROR|An uncaught error was raised while processing the update
Traceback (most recent call last):
  File "/home/matteo/Scrivania/PagRom_CPanel/lib/python3.6/site-packages/telegram/ext/dispatcher.py", line 270, in process_update
    handler.handle_update(update, self)
  File "/home/matteo/Scrivania/PagRom_CPanel/lib/python3.6/site-packages/telegram/ext/callbackqueryhandler.py", line 143, in handle_update
    return self.callback(dispatcher.bot, update, **optional_args)
  File "test.py", line 39, in button
    update.message.reply_text("hai selezionato l'opzione: {}".format(query.data))
AttributeError: 'NoneType' object has no attribute 'reply_text'
2017-12-08 01:14:03,938|ERROR|An uncaught error was raised while processing the update
Traceback (most recent call last):
  File "/home/matteo/Scrivania/PagRom_CPanel/lib/python3.6/site-packages/telegram/ext/dispatcher.py", line 270, in process_update
    handler.handle_update(update, self)
  File "/home/matteo/Scrivania/PagRom_CPanel/lib/python3.6/site-packages/telegram/ext/callbackqueryhandler.py", line 143, in handle_update
    return self.callback(dispatcher.bot, update, **optional_args)
  File "test.py", line 39, in button
    update.message.reply_text("hai selezionato l'opzione: {}".format(query.data))
AttributeError: 'NoneType' object has no attribute 'reply_text'
2017-12-08 02:16:15,779|WARNING|Exiting immediately!
2017-12-08 02:36:05,282|WARNING|Exiting immediately!
2017-12-08 15:42:58,314|ERROR|Error while getting Updates: Timed out
2017-12-08 15:56:42,299|ERROR|Error while getting Updates: Timed out
2017-12-08 16:04:52,746|ERROR|Error while getting Updates: Timed out
2017-12-08 17:00:05,765|WARNING|Exiting immediately!
2017-12-08 17:00:58,989|INFO|Gender of Matteo: Boy
2017-12-08 17:01:04,619|INFO|User Matteo did not send a photo.
2017-12-08 17:01:08,288|INFO|User Matteo did not send a location.
2017-12-08 17:01:41,773|INFO|Bio of Matteo: No
2017-12-08 17:31:24,509|ERROR|Error while getting Updates: Timed out
2017-12-08 17:31:24,520|WARNING|Update "None" caused error "Timed out"
2017-12-08 17:31:37,753|ERROR|Error while getting Updates: Timed out
2017-12-08 17:31:37,754|WARNING|Update "None" caused error "Timed out"
2017-12-08 17:44:27,029|ERROR|Error while getting Updates: Timed out
2017-12-08 17:44:27,030|WARNING|Update "None" caused error "Timed out"
2017-12-08 17:44:40,300|ERROR|Error while getting Updates: Timed out
2017-12-08 17:44:40,303|WARNING|Update "None" caused error "Timed out"
2017-12-08 17:45:54,467|ERROR|Error while getting Updates: Timed out
2017-12-08 17:45:54,470|WARNING|Update "None" caused error "Timed out"
2017-12-08 17:55:14,379|ERROR|Error while getting Updates: Timed out
2017-12-08 17:55:14,391|WARNING|Update "None" caused error "Timed out"
2017-12-08 18:24:54,038|ERROR|Error while getting Updates: Timed out
2017-12-08 18:24:54,039|WARNING|Update "None" caused error "Timed out"
2017-12-08 18:45:25,452|ERROR|Error while getting Updates: Timed out
2017-12-08 18:45:25,455|WARNING|Update "None" caused error "Timed out"
2017-12-08 18:45:38,741|ERROR|Error while getting Updates: Timed out
2017-12-08 18:45:38,742|WARNING|Update "None" caused error "Timed out"
2017-12-08 19:00:13,312|ERROR|Error while getting Updates: Timed out
2017-12-08 19:00:13,312|WARNING|Update "None" caused error "Timed out"
2017-12-08 21:24:24,773|ERROR|Error while getting Updates: Timed out
2017-12-08 21:24:24,774|WARNING|Update "None" caused error "Timed out"
2017-12-08 21:29:21,127|ERROR|Error while getting Updates: Timed out
2017-12-08 21:29:21,128|WARNING|Update "None" caused error "Timed out"
2017-12-08 21:43:22,995|ERROR|Error while getting Updates: Timed out
2017-12-08 21:43:23,015|WARNING|Update "None" caused error "Timed out"
2017-12-08 21:46:27,457|ERROR|Error while getting Updates: Timed out
2017-12-08 21:46:27,459|WARNING|Update "None" caused error "Timed out"
2017-12-08 22:17:04,814|ERROR|Error while getting Updates: Timed out
2017-12-08 22:17:04,824|WARNING|Update "None" caused error "Timed out"
2017-12-08 22:32:17,053|WARNING|Exiting immediately!
